[ ERROR ] Taking listener 'allure_robotframework' into use failed: Importing listener 'allure_robotframework' failed: ModuleNotFoundError: No module named 'allure_robotframework'
Traceback (most recent call last):
  None
PYTHONPATH:
  C:\Users\Gayathri\AppData\Local\Programs\Python\Python310\Scripts\robot.exe
  C:\Users\Gayathri\AppData\Local\Programs\Python\Python310\python310.zip
  C:\Users\Gayathri\AppData\Local\Programs\Python\Python310\DLLs
  C:\Users\Gayathri\AppData\Local\Programs\Python\Python310\lib
  C:\Users\Gayathri\AppData\Local\Programs\Python\Python310
  C:\Users\Gayathri\AppData\Local\Programs\Python\Python310\lib\site-packages
  C:\Users\Gayathri\AppData\Local\Programs\Python\Python310\lib\site-packages\win32
  C:\Users\Gayathri\AppData\Local\Programs\Python\Python310\lib\site-packages\win32\lib
  C:\Users\Gayathri\AppData\Local\Programs\Python\Python310\lib\site-packages\Pythonwin
2024-01-31 17:46:06,520 - RPA.core.certificates - INFO - Truststore not in use, HTTPS traffic validated against `certifi` package. (requires Python 3.10.12 and 'pip' 23.2.1 at minimum)
Traceback (most recent call last):
  File "C:\Users\Gayathri\AppData\Local\Programs\Python\Python310\lib\runpy.py", line 196, in _run_module_as_main
    return _run_code(code, main_globals, None,
  File "C:\Users\Gayathri\AppData\Local\Programs\Python\Python310\lib\runpy.py", line 86, in _run_code
    exec(code, run_globals)
  File "C:\Users\Gayathri\AppData\Local\Programs\Python\Python310\Scripts\pabot.exe\__main__.py", line 7, in <module>
  File "C:\Users\Gayathri\AppData\Local\Programs\Python\Python310\lib\site-packages\pabot\pabot.py", line 1876, in main
    return sys.exit(main_program(args))
  File "C:\Users\Gayathri\AppData\Local\Programs\Python\Python310\lib\site-packages\pabot\pabot.py", line 1906, in main_program
    outs_dir = _output_dir(options)
  File "C:\Users\Gayathri\AppData\Local\Programs\Python\Python310\lib\site-packages\pabot\pabot.py", line 1351, in _output_dir
    shutil.rmtree(outpath)
  File "C:\Users\Gayathri\AppData\Local\Programs\Python\Python310\lib\shutil.py", line 739, in rmtree
    return _rmtree_unsafe(path, onerror)
  File "C:\Users\Gayathri\AppData\Local\Programs\Python\Python310\lib\shutil.py", line 612, in _rmtree_unsafe
    _rmtree_unsafe(fullname, onerror)
  File "C:\Users\Gayathri\AppData\Local\Programs\Python\Python310\lib\shutil.py", line 617, in _rmtree_unsafe
    onerror(os.unlink, fullname, sys.exc_info())
  File "C:\Users\Gayathri\AppData\Local\Programs\Python\Python310\lib\shutil.py", line 615, in _rmtree_unsafe
    os.unlink(fullname)
PermissionError: [WinError 32] The process cannot access the file because it is being used by another process: '.\\output\\pabot_results\\0\\output.xml'
