2024-02-05 13:19:22,267 - RPA.core.certificates - INFO - Truststore not in use, HTTPS traffic validated against `certifi` package. (requires Python 3.10.12 and 'pip' 23.2.1 at minimum)
Traceback (most recent call last):
  File "C:\Users\amird\AppData\Local\Programs\Python\Python310\lib\runpy.py", line 196, in _run_module_as_main
    return _run_code(code, main_globals, None,
  File "C:\Users\amird\AppData\Local\Programs\Python\Python310\lib\runpy.py", line 86, in _run_code
    exec(code, run_globals)
  File "C:\Users\amird\AppData\Local\Programs\python\Python310\Scripts\pabot.exe\__main__.py", line 7, in <module>
  File "C:\Users\amird\AppData\Local\Programs\Python\Python310\lib\site-packages\pabot\pabot.py", line 1891, in main
    return sys.exit(main_program(args))
  File "C:\Users\amird\AppData\Local\Programs\Python\Python310\lib\site-packages\pabot\pabot.py", line 1921, in main_program
    outs_dir = _output_dir(options)
  File "C:\Users\amird\AppData\Local\Programs\Python\Python310\lib\site-packages\pabot\pabot.py", line 1366, in _output_dir
    shutil.rmtree(outpath)
  File "C:\Users\amird\AppData\Local\Programs\Python\Python310\lib\shutil.py", line 739, in rmtree
    return _rmtree_unsafe(path, onerror)
  File "C:\Users\amird\AppData\Local\Programs\Python\Python310\lib\shutil.py", line 612, in _rmtree_unsafe
    _rmtree_unsafe(fullname, onerror)
  File "C:\Users\amird\AppData\Local\Programs\Python\Python310\lib\shutil.py", line 617, in _rmtree_unsafe
    onerror(os.unlink, fullname, sys.exc_info())
  File "C:\Users\amird\AppData\Local\Programs\Python\Python310\lib\shutil.py", line 615, in _rmtree_unsafe
    os.unlink(fullname)
PermissionError: [WinError 32] The process cannot access the file because it is being used by another process: '.\\output\\Testcase\\pabot_results\\0\\output.xml'
